# -*- coding: utf-8 -*-
from odoo import models, fields, api, _
from odoo.exceptions import UserError
import logging
_logger = logging.getLogger(__name__)


class masive_send_dte_wizard(models.TransientModel):
    _name = 'sii.dte.pos.masive_send.wizard'
    _description = 'SII Masive send Wizard'

    @api.model
    def _getIDs(self):
        context = dict(self._context or {})
        active_ids = context.get('active_ids', []) or []
        return [(6, 0, active_ids)]

    documentos = fields.Many2many(
            'pos.order',
            string="Documentos",
            default=_getIDs,
        )
    set_pruebas = fields.Boolean(string="Es set de pruebas",
                              invisible=lambda self: self.env.user.company_id.dte_service_provider=='SIICERT',
                              default=lambda self: self.env.user.company_id.dte_service_provider=='SIICERT')

    
    def confirm(self):
        self.documentos.with_context(set_pruebas=self.set_pruebas)\
            .do_dte_send_order()
